Workbook
Name DataKet3: Hasil_PG!$T$11:$BQ$29
Name DataRek1: [1]Instrumen!$O$11:$BL$94

Sheet Menu

Sheet Petunjuk
A1: Petunjuk Pengisian
A3: 1 | B3: Pengisian Biodata
B4: 1.1 | C4: Isilah sheet 'Biodata" dengan data yang sesuai
A5: 2 | B5: Pengisian data hasil telaah soal Pilihan Ganda (PG)
B6: 2.1 | C6: Isilah kolom yang diblok warna hijau dengan tanda "V" untuk yang sesuai dan tanda "X" untuk yang tidak sesuai
A7: 3 | B7: Pengisian data hasil telaah soal Uraian (UR)
B8: 3.1 | C8: Isilah kolom yang diblok warna hijau dengan tanda "V" untuk yang sesuai dan tanda "X" untuk yang tidak sesuai
A9: 4 | B9: Mencetak laporan hasil telaah soal
B10: 4.1 | C10: Cetaklah sheet 'Ins_PG' untuk Instrumen telaah soal Pilihan Ganda
B11: 4.2 | C11: Cetaklah sheet 'Ins_UR' untuk Instrumen telaah soal Uraian
B12: 4.3 | C12: Cetaklah sheet 'Hasil_PG' untuk hasil telaah soal Pilihan Ganda
B13: 4.4 | C13: Cetaklah sheet 'Hasil_UR' untuk hasil telaah soal Uraian
B14: 4.5 | C14: Cetaklah sheet 'Rekap'
B15: 4.6 | C15: Cetaklah sheet 'BA' untuk berita acara telaah soal
A16: 5 | B16: Editorial
B17: 5.1 | C17: Untuk kepentingan menyesuaikan jumlah soal format dapat menyesuaikan dengan cara kolom di-'hidden'

Sheet Biodata
A1: BIODATA ANALISIS KUALITATIF BUTIR SOAL
A4: Sekolah | B4: : | C4: SMK NEGERI 1 JATIROTO
A5: Alamat | B5: : | C5: Jl. Raya Jatiroto, Janggan, Kec. Jatiroto, Kab. Wonogiri
A6: Mata Pelajaran | B6: : | C6: Bahasa Inggris
A7: Pengawas Pembina | B7: : | C7: Indah Darmawati, SE, M.Pd | D7: NIP | E7: : | F7: 19770316 200701 2 002
A8: Penanggung Jawab/Pendamping | B8: : | C8: Drs. Suyono, M.Si | D8: NIP | E8: : | F8: 19630329 199512 1 003
A9: Ketua Tim Teaching | B9: : | C9: Galuh Wury Prabaningrum, S.Pd. | D9: NIP | E9: : | F9: 19770321 200801 2 012
A10: Penyusun Kisi-kisi dan Soal | B10: : | C10: Bhekti Tulus Martani, S.Pd. | D10: NIP | E10: : | F10: -
A11: Penelaah | B11: : | C11: Ade Setiyawan, S.Kom. | D11: NIP | E11: : | F11: -
A12: Jumlah Soal Pilihan Ganda | B12: : | C12: =VLOOKUP(C6,[2]Sheet2!A1:D20,3) -> 40
A13: Jumlah Soal Uraian | B13: : | C13: =VLOOKUP(C6,[2]Sheet2!A1:D20,4) -> 5
A14: Kurikulum | B14: : | C14: 2013 Rev
A15: Tahun Pelajaran | B15: : | C15: 2020/2021
A16: Hari Telaah | B16: : | C16: Selasa
A17: Pelaksanaan Telaah | B17: : | C17: 16 Maret 2021
A18: Kabupaten | B18: : | C18: Wonogiri
A19: Provinsi | B19: : | C19: Jawa Tengah

Sheet Telaah_PG
A1: Petunjuk
A2: Isilah kolom telaah soal dengan tanda "V" untuk yang sesuai atau tanda "X" untuk yang tidak sesuai pada setiap cel yang diblok warna hijau
A4: NO | B4: ASPEK | C4: INDIKATOR | G4: DESKRIPTOR | I4: telaah soal | BB4: skor soal | CU4: kategori | EN4: aspek lemah | HZ4: gabungan aspek lemah | JS4: rekomendasi No.
I5: 1 | J5: 2 | K5: 3 | L5: 4 | M5: 5 | N5: 6 | O5: 7 | P5: 8 | Q5: 9 | R5: 10 | S5: 11 | T5: 12 | U5: 13 | V5: 14 | W5: 15 | X5: 16 | Y5: 17 | Z5: 18 | AA5: 19 | AB5: 20 | AC5: 21 | AD5: 22 | AE5: 23 | AF5: 24 | AG5: 25 | AH5: 26 | AI5: 27 | AJ5: 28 | AK5: 29 | AL5: 30 | AM5: 31 | AN5: 32 | AO5: 33 | AP5: 34 | AQ5: 35 | AR5: 36 | AS5: 37 | AT5: 38 | AU5: 39 | AV5: 40 | AW5: 41 | AX5: 42 | AY5: 43 | AZ5: 44 | BA5: 45 | BB5: 1 | BC5: 2 | BD5: 3 | BE5: 4 | BF5: 5 | BG5: 6 | BH5: 7 | BI5: 8 | BJ5: 9 | BK5: 10 | BL5: 11 | BM5: 12 | BN5: 13 | BO5: 14 | BP5: 15 | BQ5: 16 | BR5: 17 | BS5: 18 | BT5: 19 | BU5: 20 | BV5: 21 | BW5: 22 | BX5: 23 | BY5: 24 | BZ5: 25 | CA5: 26 | CB5: 27 | CC5: 28 | CD5: 29 | CE5: 30 | CF5: 31 | CG5: 32 | CH5: 33 | CI5: 34 | CJ5: 35 | CK5: 36 | CL5: 37 | CM5: 38 | CN5: 39 | CO5: 40 | CP5: 41 | CQ5: 42 | CR5: 43 | CS5: 44 | CT5: 45 | CU5: 1 | CV5: 2 | CW5: 3 | CX5: 4 | CY5: 5 | CZ5: 6 | DA5: 7 | DB5: 8 | DC5: 9 | DD5: 10 | DE5: 11 | DF5: 12 | DG5: 13 | DH5: 14 | DI5: 15 | DJ5: 16 | DK5: 17 | DL5: 18 | DM5: 19 | DN5: 20 | DO5: 21 | DP5: 22 | DQ5: 23 | DR5: 24 | DS5: 25 | DT5: 26 | DU5: 27 | DV5: 28 | DW5: 29 | DX5: 30 | DY5: 31 | DZ5: 32 | EA5: 33 | EB5: 34 | EC5: 35 | ED5: 36 | EE5: 37 | EF5: 38 | EG5: 39 | EH5: 40 | EI5: 41 | EJ5: 42 | EK5: 43 | EL5: 44 | EM5: 45 | EN5: 1 | EO5: 2 | EP5: 3 | EQ5: 4 | ER5: 5 | ES5: 6 | ET5: 7 | EU5: 8 | EV5: 9 | EW5: 10 | EX5: 11 | EY5: 12 | EZ5: 13 | FA5: 14 | FB5: 15 | FC5: 16 | FD5: 17 | FE5: 18 | FF5: 19 | FG5: 20 | FH5: 21 | FI5: 22 | FJ5: 23 | FK5: 24 | FL5: 25 | FM5: 26 | FN5: 27 | FO5: 28 | FP5: 29 | FQ5: 30 | FR5: 31 | FS5: 32 | FT5: 33 | FU5: 34 | FV5: 35 | FW5: 36 | FX5: 37 | FY5: 38 | FZ5: 39 | GA5: 40 | GB5: 41 | GC5: 42 | GD5: 43 | GE5: 44 | GF5: 45 | GG5: 1 | GH5: 2 | GI5: 3 | GJ5: 4 | GK5: 5 | GL5: 6 | GM5: 7 | GN5: 8 | GO5: 9 | GP5: 10 | GQ5: 11 | GR5: 12 | GS5: 13 | GT5: 14 | GU5: 15 | GV5: 16 | GW5: 17 | GX5: 18 | GY5: 19 | GZ5: 20 | HA5: 21 | HB5: 22 | HC5: 23 | HD5: 24 | HE5: 25 | HF5: 26 | HG5: 27 | HH5: 28 | HI5: 29 | HJ5: 30 | HK5: 31 | HL5: 32 | HM5: 33 | HN5: 34 | HO5: 35 | HP5: 36 | HQ5: 37 | HR5: 38 | HS5: 39 | HT5: 40 | HU5: 41 | HV5: 42 | HW5: 43 | HX5: 44 | HY5: 45 | HZ5: 1 | IA5: 2 | IB5: 3 | IC5: 4 | ID5: 5 | IE5: 6 | IF5: 7 | IG5: 8 | IH5: 9 | II5: 10 | IJ5: 11 | IK5: 12 | IL5: 13 | IM5: 14 | IN5: 15 | IO5: 16 | IP5: 17 | IQ5: 18 | IR5: 19 | IS5: 20 | IT5: 21 | IU5: 22 | IV5: 23 | IW5: 24 | IX5: 25 | IY5: 26 | IZ5: 27 | JA5: 28 | JB5: 29 | JC5: 30 | JD5: 31 | JE5: 32 | JF5: 33 | JG5: 34 | JH5: 35 | JI5: 36 | JJ5: 37 | JK5: 38 | JL5: 39 | JM5: 40 | JN5: 41 | JO5: 42 | JP5: 43 | JQ5: 44 | JR5: 45 | JS5: 1 | JT5: 2 | JU5: 3 | JV5: 4 | JW5: 5 | JX5: 6 | JY5: 7 | JZ5: 8 | KA5: 9 | KB5: 10 | KC5: 11 | KD5: 12 | KE5: 13 | KF5: 14 | KG5: 15 | KH5: 16 | KI5: 17 | KJ5: 18 | KK5: 19 | KL5: 20 | KM5: 21 | KN5: 22 | KO5: 23 | KP5: 24 | KQ5: 25 | KR5: 26 | KS5: 27 | KT5: 28 | KU5: 29 | KV5: 30 | KW5: 31 | KX5: 32 | KY5: 33 | KZ5: 34 | LA5: 35 | LB5: 36 | LC5: 37 | LD5: 38 | LE5: 39 | LF5: 40 | LG5: 41 | LH5: 42 | LI5: 43 | LJ5: 44 | LK5: 45
A6: I. | B6: HAL-HAL PENTING | C6: A. | D6: Soal tidak menyinggung SARA | G6: ● | H6: tidak menyinggung suku | I6: v | J6: v | K6: v | L6: v | M6: v | N6: v | O6: v | P6: v | Q6: v | R6: v | S6: v | T6: v | U6: v | V6: v | W6: v | X6: v | Y6: v | Z6: v | AA6: v | AB6: v | AC6: v | AD6: v | AE6: v | AF6: v | AG6: v | AH6: v | AI6: v | AJ6: v | AK6: v | AL6: v | AM6: v | AN6: v | AO6: v | AP6: v | AQ6: v | AR6: v | AS6: v | AT6: v | AU6: v | AV6: v | BB6: =IF(AND(I6="",I7="",I8="",I9=""),"",IF(COUNTIF(I6:I9,"v")>=3,2,IF(AND(COUNTIF(I6:I9,"v")>=1,COUNTIF(I6:I9,"v")<=3),1,0))) -> 2 | BC6: =IF(AND(J6="",J7="",J8="",J9=""),"",IF(COUNTIF(J6:J9,"v")>=3,2,IF(AND(COUNTIF(J6:J9,"v")>=1,COUNTIF(J6:J9,"v")<=3),1,0))) -> 2 | BD6: =IF(AND(K6="",K7="",K8="",K9=""),"",IF(COUNTIF(K6:K9,"v")>=3,2,IF(AND(COUNTIF(K6:K9,"v")>=1,COUNTIF(K6:K9,"v")<=3),1,0))) -> 2 | BE6: =IF(AND(L6="",L7="",L8="",L9=""),"",IF(COUNTIF(L6:L9,"v")>=3,2,IF(AND(COUNTIF(L6:L9,"v")>=1,COUNTIF(L6:L9,"v")<=3),1,0))) -> 2 | BF6: =IF(AND(M6="",M7="",M8="",M9=""),"",IF(COUNTIF(M6:M9,"v")>=3,2,IF(AND(COUNTIF(M6:M9,"v")>=1,COUNTIF(M6:M9,"v")<=3),1,0))) -> 2 | BG6: =IF(AND(N6="",N7="",N8="",N9=""),"",IF(COUNTIF(N6:N9,"v")>=3,2,IF(AND(COUNTIF(N6:N9,"v")>=1,COUNTIF(N6:N9,"v")<=3),1,0))) -> 2 | BH6: =IF(AND(O6="",O7="",O8="",O9=""),"",IF(COUNTIF(O6:O9,"v")>=3,2,IF(AND(COUNTIF(O6:O9,"v")>=1,COUNTIF(O6:O9,"v")<=3),1,0))) -> 2 | BI6: =IF(AND(P6="",P7="",P8="",P9=""),"",IF(COUNTIF(P6:P9,"v")>=3,2,IF(AND(COUNTIF(P6:P9,"v")>=1,COUNTIF(P6:P9,"v")<=3),1,0))) -> 2 | ... CT6: =IF(AND(BA6="",BA7="",BA8="",BA9=""),"",IF(COUNTIF(BA6:BA9,"v")>=3,2,IF(AND(COUNTIF(BA6:BA9,"v")>=1,COUNTIF(BA6:BA9,"v")<=3),1,0))) | CU6: =IF(BB6="","",IF(BB6=0,"Ditolak",IF(BB6=1,"Diperbaiki","Digunakan"))) -> Digunakan | CV6: =IF(BC6="","",IF(BC6=0,"Ditolak",IF(AND(BC6>=1,BC6<4),"Diperbaiki","Digunakan"))) -> Diperbaiki | CW6: =IF(BD6="","",IF(BD6=0,"Ditolak",IF(AND(BD6>=1,BD6<4),"Diperbaiki","Digunakan"))) -> Diperbaiki | CX6: =IF(BE6="","",IF(BE6=0,"Ditolak",IF(AND(BE6>=1,BE6<4),"Diperbaiki","Digunakan"))) -> Diperbaiki | CY6: =IF(BF6="","",IF(BF6=0,"Ditolak",IF(AND(BF6>=1,BF6<4),"Diperbaiki","Digunakan"))) -> Diperbaiki | CZ6: =IF(BG6="","",IF(BG6=0,"Ditolak",IF(AND(BG6>=1,BG6<4),"Diperbaiki","Digunakan"))) -> Diperbaiki | DA6: =IF(BH6="","",IF(BH6=0,"Ditolak",IF(AND(BH6>=1,BH6<4),"Diperbaiki","Digunakan"))) -> Diperbaiki | DB6: =IF(BI6="","",IF(BI6=0,"Ditolak",IF(AND(BI6>=1,BI6<4),"Diperbaiki","Digunakan"))) -> Diperbaiki | DC6: =IF(BJ6="","",IF(BJ6=0,"Ditolak",IF(AND(BJ6>=1,BJ6<4),"Diperbaiki","Digunakan"))) -> Diperbaiki | ... EM6: =IF(CT6="","",IF(CT6=0,"Ditolak",IF(AND(CT6>=1,CT6<4),"Diperbaiki","Digunakan"))) | EN6: =IF(COUNTIF(CU6:CU14,"Diperbaiki")>=1,"hal-hal penting","") | EO6: =IF(COUNTIF(CV6:CV14,"Diperbaiki")>=1,"hal-hal penting","") -> hal-hal penting | EP6: =IF(COUNTIF(CW6:CW14,"Diperbaiki")>=1,"hal-hal penting","") -> hal-hal penting | EQ6: =IF(COUNTIF(CX6:CX14,"Diperbaiki")>=1,"hal-hal penting","") -> hal-hal penting | ER6: =IF(COUNTIF(CY6:CY14,"Diperbaiki")>=1,"hal-hal penting","") -> hal-hal penting | ES6: =IF(COUNTIF(CZ6:CZ14,"Diperbaiki")>=1,"hal-hal penting","") -> hal-hal penting | ET6: =IF(COUNTIF(DA6:DA14,"Diperbaiki")>=1,"hal-hal penting","") -> hal-hal penting | EU6: =IF(COUNTIF(DB6:DB14,"Diperbaiki")>=1,"hal-hal penting","") -> hal-hal penting | ... GF6: =IF(COUNTIF(EM6:EM14,"Diperbaiki")>=1,"hal-hal penting","") | GG6: =IF(EN6="","",",") | GH6: =IF(EO6="","",",") -> , | GI6: =IF(EP6="","",",") -> , | GJ6: =IF(EQ6="","",",") -> , | GK6: =IF(ER6="","",",") -> , | GL6: =IF(ES6="","",",") -> , | GM6: =IF(ET6="","",",") -> , | GN6: =IF(EU6="","",",") -> , | ... HY6: =IF(GF6="","",",") | HZ6: =CONCATENATE(EN6,GG6," ",EN15,GG15," ",EN21,GG21," ",EN39,GG39," ",EN47) -> HOTS | IA6: =CONCATENATE(EO6,GH6," ",EO15,GH15," ",EO21,GH21," ",EO39,GH39," ",EO47) -> hal-hal penting, HOTS | IB6: =CONCATENATE(EP6,GI6," ",EP15,GI15," ",EP21,GI21," ",EP39,GI39," ",EP47) -> hal-hal penting, HOTS | IC6: =CONCATENATE(EQ6,GJ6," ",EQ15,GJ15," ",EQ21,GJ21," ",EQ39,GJ39," ",EQ47) -> hal-hal penting, HOTS | ID6: =CONCATENATE(ER6,GK6," ",ER15,GK15," ",ER21,GK21," ",ER39,GK39," ",ER47) -> hal-hal penting, HOTS | IE6: =CONCATENATE(ES6,GL6," ",ES15,GL15," ",ES21,GL21," ",ES39,GL39," ",ES47) -> hal-hal penting, HOTS | IF6: =CONCATENATE(ET6,GM6," ",ET15,GM15," ",ET21,GM21," ",ET39,GM39," ",ET47) -> hal-hal penting, HOTS | IG6: =CONCATENATE(EU6,GN6," ",EU15,GN15," ",EU21,GN21," ",EU39,GN39," ",EU47) -> hal-hal penting, HOTS | ... JR6: =CONCATENATE(GF6,HY6," ",GF15,HY15," ",GF21,HY21," ",GF39,HY39," ",GF47) | JS6: =IF(HZ6="",CONCATENATE("Soal No."," ",JS5," ","dapat digunakan"),CONCATENATE("Soal No."," ",JS5," ","perlu perbaikan pada aspek"," ",HZ6)) -> Soal No. 1 perlu perbaikan pada aspek HOTS | JT6: =IF(IA6="",CONCATENATE("Soal No."," ",JT5," ","dapat digunakan"),CONCATENATE("Soal No."," ",JT5," ","perlu perbaikan pada aspek"," ",IA6)) -> Soal No. 2 perlu perbaikan pada aspek hal-hal penting, HOTS | JU6: =IF(IB6="",CONCATENATE("Soal No."," ",JU5," ","dapat digunakan"),CONCATENATE("Soal No."," ",JU5," ","perlu perbaikan pada aspek"," ",IB6)) -> Soal No. 3 perlu perbaikan pada aspek hal-hal penting, HOTS | JV6: =IF(IC6="",CONCATENATE("Soal No."," ",JV5," ","dapat digunakan"),CONCATENATE("Soal No."," ",JV5," ","perlu perbaikan pada aspek"," ",IC6)) -> Soal No. 4 perlu perbaikan pada aspek hal-hal penting, HOTS | JW6: =IF(ID6="",CONCATENATE("Soal No."," ",JW5," ","dapat digunakan"),CONCATENATE("Soal No."," ",JW5," ","perlu perbaikan pada aspek"," ",ID6)) -> Soal No. 5 perlu perbaikan pada aspek hal-hal penting, HOTS | JX6: =IF(IE6="",CONCATENATE("Soal No."," ",JX5," ","dapat digunakan"),CONCATENATE("Soal No."," ",JX5," ","perlu perbaikan pada aspek"," ",IE6)) -> Soal No. 6 perlu perbaikan pada aspek hal-hal penting, HOTS | JY6: =IF(IF6="",CONCATENATE("Soal No."," ",JY5," ","dapat digunakan"),CONCATENATE("Soal No."," ",JY5," ","perlu perbaikan pada aspek"," ",IF6)) -> Soal No. 7 perlu perbaikan pada aspek hal-hal penting, HOTS | JZ6: =IF(IG6="",CONCATENATE("Soal No."," ",JZ5," ","dapat digunakan"),CONCATENATE("Soal No."," ",JZ5," ","perlu perbaikan pada aspek"," ",IG6)) -> Soal No. 8 perlu perbaikan pada aspek hal-hal penting, HOTS | ... LK6: =IF(JR6="",CONCATENATE("Soal No."," ",LK5," ","dapat digunakan"),CONCATENATE("Soal No."," ",LK5," ","perlu perbaikan pada aspek"," ",JR6)) -> Soal No. 45 perlu perbaikan pada aspek
G7: ● | H7: tidak menyinggung agama | I7: v | J7: v | K7: v | L7: v | M7: v | N7: v | O7: v | P7: v | Q7: v | R7: v | S7: v | T7: v | U7: v | V7: v | W7: v | X7: v | Y7: v | Z7: v | AA7: v | AB7: v | AC7: v | AD7: v | AE7: v | AF7: v | AG7: v | AH7: v | AI7: v | AJ7: v | AK7: v | AL7: v | AM7: v | AN7: v | AO7: v | AP7: v | AQ7: v | AR7: v | AS7: v | AT7: v | AU7: v | AV7: v
G8: ● | H8: tidak menyinggung ras | I8: v | J8: v | K8: v | L8: v | M8: v | N8: v | O8: v | P8: v | Q8: v | R8: v | S8: v | T8: v | U8: v | V8: v | W8: v | X8: v | Y8: v | Z8: v | AA8: v | AB8: v | AC8: v | AD8: v | AE8: v | AF8: v | AG8: v | AH8: v | AI8: v | AJ8: v | AK8: v | AL8: v | AM8: v | AN8: v | AO8: v | AP8: v | AQ8: v | AR8: v | AS8: v | AT8: v | AU8: v | AV8: v | BB8: =IF(AND(I8="",I9=""),"",COUNTIF(I8:I9,"v")) -> 2 | BC8: =IF(AND(J8="",J9=""),"",COUNTIF(J8:J9,"v")) -> 2 | BD8: =IF(AND(K8="",K9=""),"",COUNTIF(K8:K9,"v")) -> 2 | BE8: =IF(AND(L8="",L9=""),"",COUNTIF(L8:L9,"v")) -> 2 | BF8: =IF(AND(M8="",M9=""),"",COUNTIF(M8:M9,"v")) -> 2 | BG8: =IF(AND(N8="",N9=""),"",COUNTIF(N8:N9,"v")) -> 2 | BH8: =IF(AND(O8="",O9=""),"",COUNTIF(O8:O9,"v")) -> 2 | BI8: =IF(AND(P8="",P9=""),"",COUNTIF(P8:P9,"v")) -> 2 | ... CT8: =IF(AND(BA8="",BA9=""),"",COUNTIF(BA8:BA9,"v"))
G9: ● | H9: tidak menyinggung antar golongan | I9: v | J9: v | K9: v | L9: v | M9: v | N9: v | O9: v | P9: v | Q9: v | R9: v | S9: v | T9: v | U9: v | V9: v | W9: v | X9: v | Y9: v | Z9: v | AA9: v | AB9: v | AC9: v | AD9: v | AE9: v | AF9: v | AG9: v | AH9: v | AI9: v | AJ9: v | AK9: v | AL9: v | AM9: v | AN9: v | AO9: v | AP9: v | AQ9: v | AR9: v | AS9: v | AT9: v | AU9: v | AV9: v
C10: B. | D10: Soal tidak bermuatan politik, pornografi, promosi produk komersil (iklan), kekerasan, dan bentuk lainnya yang dapat menimbulkan efek negatif | G10: ● | H10: tidak bermuatan politik | I10: v | J10: v | K10: v | L10: v | M10: v | N10: v | O10: v | P10: v | Q10: v | R10: v | S10: v | T10: v | U10: v | V10: v | W10: v | X10: v | Y10: v | Z10: v | AA10: v | AB10: v | AC10: v | AD10: v | AE10: v | AF10: v | AG10: v | AH10: v | AI10: v | AJ10: v | AK10: v | AL10: v | AM10: v | AN10: v | AO10: v | AP10: v | AQ10: v | AR10: v | AS10: v | AT10: v | AU10: v | AV10: v | BB10: =IF(AND(I10="",I11="",I12="",I13="",I14=""),"",IF(COUNTIF(I10:I14,"v")>=3,2,IF(AND(COUNTIF(I10:I14,"v")>=1,COUNTIF(I10:I14,"v")<=3),1,0))) -> 2 | BC10: =IF(AND(J10="",J11="",J12="",J13="",J14=""),"",IF(COUNTIF(J10:J14,"v")>=3,2,IF(AND(COUNTIF(J10:J14,"v")>=1,COUNTIF(J10:J14,"v")<=3),1,0))) -> 2 | BD10: =IF(AND(K10="",K11="",K12="",K13="",K14=""),"",IF(COUNTIF(K10:K14,"v")>=3,2,IF(AND(COUNTIF(K10:K14,"v")>=1,COUNTIF(K10:K14,"v")<=3),1,0))) -> 2 | BE10: =IF(AND(L10="",L11="",L12="",L13="",L14=""),"",IF(COUNTIF(L10:L14,"v")>=3,2,IF(AND(COUNTIF(L10:L14,"v")>=1,COUNTIF(L10:L14,"v")<=3),1,0))) -> 2 | BF10: =IF(AND(M10="",M11="",M12="",M13="",M14=""),"",IF(COUNTIF(M10:M14,"v")>=3,2,IF(AND(COUNTIF(M10:M14,"v")>=1,COUNTIF(M10:M14,"v")<=3),1,0))) -> 2 | BG10: =IF(AND(N10="",N11="",N12="",N13="",N14=""),"",IF(COUNTIF(N10:N14,"v")>=3,2,IF(AND(COUNTIF(N10:N14,"v")>=1,COUNTIF(N10:N14,"v")<=3),1,0))) -> 2 | BH10: =IF(AND(O10="",O11="",O12="",O13="",O14=""),"",IF(COUNTIF(O10:O14,"v")>=3,2,IF(AND(COUNTIF(O10:O14,"v")>=1,COUNTIF(O10:O14,"v")<=3),1,0))) -> 2 | BI10: =IF(AND(P10="",P11="",P12="",P13="",P14=""),"",IF(COUNTIF(P10:P14,"v")>=3,2,IF(AND(COUNTIF(P10:P14,"v")>=1,COUNTIF(P10:P14,"v")<=3),1,0))) -> 2 | ... CT10: =IF(AND(BA10="",BA11="",BA12="",BA13="",BA14=""),"",IF(COUNTIF(BA10:BA14,"v")>=3,2,IF(AND(COUNTIF(BA10:BA14,"v")>=1,COUNTIF(BA10:BA14,"v")<=3),1,0))) | CU10: =IF(BB10="","",IF(BB10=0,"Ditolak",IF(BB10=1,"Diperbaiki","Digunakan"))) -> Digunakan | CV10: =IF(BC10="","",IF(BC10=0,"Ditolak",IF(AND(BC10>=1,BC10<4),"Diperbaiki","Digunakan"))) -> Diperbaiki | CW10: =IF(BD10="","",IF(BD10=0,"Ditolak",IF(AND(BD10>=1,BD10<4),"Diperbaiki","Digunakan"))) -> Diperbaiki | CX10: =IF(BE10="","",IF(BE10=0,"Ditolak",IF(AND(BE10>=1,BE10<4),"Diperbaiki","Digunakan"))) -> Diperbaiki | CY10: =IF(BF10="","",IF(BF10=0,"Ditolak",IF(AND(BF10>=1,BF10<4),"Diperbaiki","Digunakan"))) -> Diperbaiki | CZ10: =IF(BG10="","",IF(BG10=0,"Ditolak",IF(AND(BG10>=1,BG10<4),"Diperbaiki","Digunakan"))) -> Diperbaiki | DA10: =IF(BH10="","",IF(BH10=0,"Ditolak",IF(AND(BH10>=1,BH10<4),"Diperbaiki","Digunakan"))) -> Diperbaiki | DB10: =IF(BI10="","",IF(BI10=0,"Ditolak",IF(AND(BI10>=1,BI10<4),"Diperbaiki","Digunakan"))) -> Diperbaiki | DC10: =IF(BJ10="","",IF(BJ10=0,"Ditolak",IF(AND(BJ10>=1,BJ10<4),"Diperbaiki","Digunakan"))) -> Diperbaiki | ... EM10: =IF(CT10="","",IF(CT10=0,"Ditolak",IF(AND(CT10>=1,CT10<4),"Diperbaiki","Digunakan")))
G11: ● | H11: tidak bermuatan pornografi | I11: v | J11: v | K11: v | L11: v | M11: v | N11: v | O11: v | P11: v | Q11: v | R11: v | S11: v | T11: v | U11: v | V11: v | W11: v | X11: v | Y11: v | Z11: v | AA11: v | AB11: v | AC11: v | AD11: v | AE11: v | AF11: v | AG11: v | AH11: v | AI11: v | AJ11: v | AK11: v | AL11: v | AM11: v | AN11: v | AO11: v | AP11: v | AQ11: v | AR11: v | AS11: v | AT11: v | AU11: v | AV11: v
G12: ● | H12: tidak bermuatan promosi | I12: v | J12: v | K12: v | L12: v | M12: v | N12: v | O12: v | P12: v | Q12: v | R12: v | S12: v | T12: v | U12: v | V12: v | W12: v | X12: v | Y12: v | Z12: v | AA12: v | AB12: v | AC12: v | AD12: v | AE12: v | AF12: v | AG12: v | AH12: v | AI12: v | AJ12: v | AK12: v | AL12: v | AM12: v | AN12: v | AO12: v | AP12: v | AQ12: v | AR12: v | AS12: v | AT12: v | AU12: v | AV12: v
G13: ● | H13: tidak bermuatan kekerasan | I13: v | J13: v | K13: v | L13: v | M13: v | N13: v | O13: v | P13: v | Q13: v | R13: v | S13: v | T13: v | U13: v | V13: v | W13: v | X13: v | Y13: v | Z13: v | AA13: v | AB13: v | AC13: v | AD13: v | AE13: v | AF13: v | AG13: v | AH13: v | AI13: v | AJ13: v | AK13: v | AL13: v | AM13: v | AN13: v | AO13: v | AP13: v | AQ13: v | AR13: v | AS13: v | AT13: v | AU13: v | AV13: v
G14: ● | H14: tidak menimbulkann efek negatif lainnya | I14: v | J14: v | K14: v | L14: v | M14: v | N14: v | O14: v | P14: v | Q14: v | R14: v | S14: v | T14: v | U14: v | V14: v | W14: v | X14: v | Y14: v | Z14: v | AA14: v | AB14: v | AC14: v | AD14: v | AE14: v | AF14: v | AG14: v | AH14: v | AI14: v | AJ14: v | AK14: v | AL14: v | AM14: v | AN14: v | AO14: v | AP14: v | AQ14: v | AR14: v | AS14: v | AT14: v | AU14: v | AV14: v
A15: II. | B15: KAIDAH PENULISAN SOAL | C15: A. | D15: MATERI | E15: 1 | F15: Soal sesuai dengan indikator. | G15: ● | H15: sesuai kisi-kisi soal yang ditetapkan | I15: v | J15: v | K15: v | L15: v | M15: v | N15: v | O15: v | P15: v | Q15: v | R15: v | S15: v | T15: v | U15: v | V15: v | W15: v | X15: v | Y15: v | Z15: v | AA15: v | AB15: v | AC15: v | AD15: v | AE15: v | AF15: v | AG15: v | AH15: v | AI15: v | AJ15: v | AK15: v | AL15: v | AM15: v | AN15: v | AO15: v | AP15: v | AQ15: v | AR15: v | AS15: v | AT15: v | AU15: v | AV15: v | BB15: =IF(AND(I15="",I16=""),"",COUNTIF(I15:I16,"v")) -> 2 | BC15: =IF(AND(J15="",J16=""),"",COUNTIF(J15:J16,"v")) -> 2 | BD15: =IF(AND(K15="",K16=""),"",COUNTIF(K15:K16,"v")) -> 2 | BE15: =IF(AND(L15="",L16=""),"",COUNTIF(L15:L16,"v")) -> 2 | BF15: =IF(AND(M15="",M16=""),"",COUNTIF(M15:M16,"v")) -> 2 | BG15: =IF(AND(N15="",N16=""),"",COUNTIF(N15:N16,"v")) -> 2 | BH15: =IF(AND(O15="",O16=""),"",COUNTIF(O15:O16,"v")) -> 2 | BI15: =IF(AND(P15="",P16=""),"",COUNTIF(P15:P16,"v")) -> 2 | ... CT15: =IF(AND(BA15="",BA16=""),"",COUNTIF(BA15:BA16,"v")) | CU15: =IF(BB15="","",IF(BB15=0,"Ditolak",IF(BB15=1,"Diperbaiki","Digunakan"))) -> Digunakan | CV15: =IF(BC15="","",IF(BC15=0,"Ditolak",IF(AND(BC15>=1,BC15<2),"Diperbaiki","Digunakan"))) -> Digunakan | CW15: =IF(BD15="","",IF(BD15=0,"Ditolak",IF(AND(BD15>=1,BD15<2),"Diperbaiki","Digunakan"))) -> Digunakan | CX15: =IF(BE15="","",IF(BE15=0,"Ditolak",IF(AND(BE15>=1,BE15<2),"Diperbaiki","Digunakan"))) -> Digunakan | CY15: =IF(BF15="","",IF(BF15=0,"Ditolak",IF(AND(BF15>=1,BF15<2),"Diperbaiki","Digunakan"))) -> Digunakan | CZ15: =IF(BG15="","",IF(BG15=0,"Ditolak",IF(AND(BG15>=1,BG15<2),"Diperbaiki","Digunakan"))) -> Digunakan | DA15: =IF(BH15="","",IF(BH15=0,"Ditolak",IF(AND(BH15>=1,BH15<2),"Diperbaiki","Digunakan"))) -> Digunakan | DB15: =IF(BI15="","",IF(BI15=0,"Ditolak",IF(AND(BI15>=1,BI15<2),"Diperbaiki","Digunakan"))) -> Digunakan | DC15: =IF(BJ15="","",IF(BJ15=0,"Ditolak",IF(AND(BJ15>=1,BJ15<2),"Diperbaiki","Digunakan"))) -> Digunakan | ... EM15: =IF(CT15="","",IF(CT15=0,"Ditolak",IF(AND(CT15>=1,CT15<2),"Diperbaiki","Digunakan"))) | EN15: =IF(COUNTIF(CU15:CU20,"Diperbaiki")>=1,"materi","") | EO15: =IF(COUNTIF(CV15:CV20,"Diperbaiki")>=1,"materi","") | EP15: =IF(COUNTIF(CW15:CW20,"Diperbaiki")>=1,"materi","") | EQ15: =IF(COUNTIF(CX15:CX20,"Diperbaiki")>=1,"materi","") | ER15: =IF(COUNTIF(CY15:CY20,"Diperbaiki")>=1,"materi","") | ES15: =IF(COUNTIF(CZ15:CZ20,"Diperbaiki")>=1,"materi","") | ET15: =IF(COUNTIF(DA15:DA20,"Diperbaiki")>=1,"materi","") | EU15: =IF(COUNTIF(DB15:DB20,"Diperbaiki")>=1,"materi","") | ... GF15: =IF(COUNTIF(EM15:EM20,"Diperbaiki")>=1,"materi","") | GG15: =IF(EN15="","",",") | GH15: =IF(EO15="","",",") | GI15: =IF(EP15="","",",") | GJ15: =IF(EQ15="","",",") | GK15: =IF(ER15="","",",") | GL15: =IF(ES15="","",",") | GM15: =IF(ET15="","",",") | GN15: =IF(EU15="","",",") | ... HY15: =IF(GF15="","",",")
G16: ● | H16: menanyakan perilaku dan materi yang akan diukur | I16: v | J16: v | K16: v | L16: v | M16: v | N16: v | O16: v | P16: v | Q16: v | R16: v | S16: v | T16: v | U16: v | V16: v | W16: v | X16: v | Y16: v | Z16: v | AA16: v | AB16: v | AC16: v | AD16: v | AE16: v | AF16: v | AG16: v | AH16: v | AI16: v | AJ16: v | AK16: v | AL16: v | AM16: v | AN16: v | AO16: v | AP16: v | AQ16: v | AR16: v | AS16: v | AT16: v | AU16: v | AV16: v
E17: 2 | F17: Pilihan jawaban homogen dan logis | G17: ● | H17: pilihan jawaban homogin | I17: v | J17: v | K17: v | L17: v | M17: v | N17: v | O17: v | P17: v | Q17: v | R17: v | S17: v | T17: v | U17: v | V17: v | W17: v | X17: v | Y17: v | Z17: v | AA17: v | AB17: v | AC17: v | AD17: v | AE17: v | AF17: v | AG17: v | AH17: v | AI17: v | AJ17: v | AK17: v | AL17: v | AM17: v | AN17: v | AO17: v | AP17: v | AQ17: v | AR17: v | AS17: v | AT17: v | AU17: v | AV17: v | BB17: =IF(AND(I17="",I18=""),"",COUNTIF(I17:I18,"v")) -> 2 | BC17: =IF(AND(J17="",J18=""),"",COUNTIF(J17:J18,"v")) -> 2 | BD17: =IF(AND(K17="",K18=""),"",COUNTIF(K17:K18,"v")) -> 2 | BE17: =IF(AND(L17="",L18=""),"",COUNTIF(L17:L18,"v")) -> 2 | BF17: =IF(AND(M17="",M18=""),"",COUNTIF(M17:M18,"v")) -> 2 | BG17: =IF(AND(N17="",N18=""),"",COUNTIF(N17:N18,"v")) -> 2 | BH17: =IF(AND(O17="",O18=""),"",COUNTIF(O17:O18,"v")) -> 2 | BI17: =IF(AND(P17="",P18=""),"",COUNTIF(P17:P18,"v")) -> 2 | ... CT17: =IF(AND(BA17="",BA18=""),"",COUNTIF(BA17:BA18,"v")) | CU17: =IF(BB17="","",IF(BB17=0,"Ditolak",IF(BB17=1,"Diperbaiki","Digunakan"))) -> Digunakan | CV17: =IF(BC17="","",IF(BC17=0,"Ditolak",IF(AND(BC17>=1,BC17<2),"Diperbaiki","Digunakan"))) -> Digunakan | CW17: =IF(BD17="","",IF(BD17=0,"Ditolak",IF(AND(BD17>=1,BD17<2),"Diperbaiki","Digunakan"))) -> Digunakan | CX17: =IF(BE17="","",IF(BE17=0,"Ditolak",IF(AND(BE17>=1,BE17<2),"Diperbaiki","Digunakan"))) -> Digunakan | CY17: =IF(BF17="","",IF(BF17=0,"Ditolak",IF(AND(BF17>=1,BF17<2),"Diperbaiki","Digunakan"))) -> Digunakan | CZ17: =IF(BG17="","",IF(BG17=0,"Ditolak",IF(AND(BG17>=1,BG17<2),"Diperbaiki","Digunakan"))) -> Digunakan | DA17: =IF(BH17="","",IF(BH17=0,"Ditolak",IF(AND(BH17>=1,BH17<2),"Diperbaiki","Digunakan"))) -> Digunakan | DB17: =IF(BI17="","",IF(BI17=0,"Ditolak",IF(AND(BI17>=1,BI17<2),"Diperbaiki","Digunakan"))) -> Digunakan | DC17: =IF(BJ17="","",IF(BJ17=0,"Ditolak",IF(AND(BJ17>=1,BJ17<2),"Diperbaiki","Digunakan"))) -> Digunakan | ... EM17: =IF(CT17="","",IF(CT17=0,"Ditolak",IF(AND(CT17>=1,CT17<2),"Diperbaiki","Digunakan")))
G18: ● | H18: pilihan jawaban logis | I18: v | J18: v | K18: v | L18: v | M18: v | N18: v | O18: v | P18: v | Q18: v | R18: v | S18: v | T18: v | U18: v | V18: v | W18: v | X18: v | Y18: v | Z18: v | AA18: v | AB18: v | AC18: v | AD18: v | AE18: v | AF18: v | AG18: v | AH18: v | AI18: v | AJ18: v | AK18: v | AL18: v | AM18: v | AN18: v | AO18: v | AP18: v | AQ18: v | AR18: v | AS18: v | AT18: v | AU18: v | AV18: v
E19: 3 | F19: Soal mempunyai satu jawaban yang benar atau yang paling benar. | G19: ● | H19: bentuk soal pilihan ganda dengan 5 opsi | I19: v | J19: v | K19: v | L19: v | M19: v | N19: v | O19: v | P19: v | Q19: v | R19: v | S19: v | T19: v | U19: v | V19: v | W19: v | X19: v | Y19: v | Z19: v | AA19: v | AB19: v | AC19: v | AD19: v | AE19: v | AF19: v | AG19: v | AH19: v | AI19: v | AJ19: v | AK19: v | AL19: v | AM19: v | AN19: v | AO19: v | AP19: v | AQ19: v | AR19: v | AS19: v | AT19: v | AU19: v | AV19: v | BB19: =IF(AND(I19="",I20=""),"",COUNTIF(I19:I20,"v")) -> 2 | BC19: =IF(AND(J19="",J20=""),"",COUNTIF(J19:J20,"v")) -> 2 | BD19: =IF(AND(K19="",K20=""),"",COUNTIF(K19:K20,"v")) -> 2 | BE19: =IF(AND(L19="",L20=""),"",COUNTIF(L19:L20,"v")) -> 2 | BF19: =IF(AND(M19="",M20=""),"",COUNTIF(M19:M20,"v")) -> 2 | BG19: =IF(AND(N19="",N20=""),"",COUNTIF(N19:N20,"v")) -> 2 | BH19: =IF(AND(O19="",O20=""),"",COUNTIF(O19:O20,"v")) -> 2 | BI19: =IF(AND(P19="",P20=""),"",COUNTIF(P19:P20,"v")) -> 2 | ... CT19: =IF(AND(BA19="",BA20=""),"",COUNTIF(BA19:BA20,"v")) | CU19: =IF(BB19="","",IF(BB19=0,"Ditolak",IF(BB19=1,"Diperbaiki","Digunakan"))) -> Digunakan | CV19: =IF(BC19="","",IF(BC19=0,"Ditolak",IF(AND(BC19>=1,BC19<2),"Diperbaiki","Digunakan"))) -> Digunakan | CW19: =IF(BD19="","",IF(BD19=0,"Ditolak",IF(AND(BD19>=1,BD19<2),"Diperbaiki","Digunakan"))) -> Digunakan | CX19: =IF(BE19="","",IF(BE19=0,"Ditolak",IF(AND(BE19>=1,BE19<2),"Diperbaiki","Digunakan"))) -> Digunakan | CY19: =IF(BF19="","",IF(BF19=0,"Ditolak",IF(AND(BF19>=1,BF19<2),"Diperbaiki","Digunakan"))) -> Digunakan | CZ19: =IF(BG19="","",IF(BG19=0,"Ditolak",IF(AND(BG19>=1,BG19<2),"Diperbaiki","Digunakan"))) -> Digunakan | DA19: =IF(BH19="","",IF(BH19=0,"Ditolak",IF(AND(BH19>=1,BH19<2),"Diperbaiki","Digunakan"))) -> Digunakan | DB19: =IF(BI19="","",IF(BI19=0,"Ditolak",IF(AND(BI19>=1,BI19<2),"Diperbaiki","Digunakan"))) -> Digunakan | DC19: =IF(BJ19="","",IF(BJ19=0,"Ditolak",IF(AND(BJ19>=1,BJ19<2),"Diperbaiki","Digunakan"))) -> Digunakan | ... EM19: =IF(CT19="","",IF(CT19=0,"Ditolak",IF(AND(CT19>=1,CT19<2),"Diperbaiki","Digunakan")))
G20: ● | H20: mempunyai satu jawaban benar | I20: v | J20: v | K20: v | L20: v | M20: v | N20: v | O20: v | P20: v | Q20: v | R20: v | S20: v | T20: v | U20: v | V20: v | W20: v | X20: v | Y20: v | Z20: v | AA20: v | AB20: v | AC20: v | AD20: v | AE20: v | AF20: v | AG20: v | AH20: v | AI20: v | AJ20: v | AK20: v | AL20: v | AM20: v | AN20: v | AO20: v | AP20: v | AQ20: v | AR20: v | AS20: v | AT20: v | AU20: v | AV20: v
C21: B. | D21: KONSTRUKSI | E21: 1 | F21: Pokok soal dirumuskan secara jelas dan tegas. | G21: ● | H21: pokok soal tidak membingungkan peserta ujian | I21: v | J21: v | K21: v | L21: v | M21: v | N21: v | O21: v | P21: v | Q21: v | R21: v | S21: v | T21: v | U21: v | V21: v | W21: v | X21: v | Y21: v | Z21: v | AA21: v | AB21: v | AC21: v | AD21: v | AE21: v | AF21: v | AG21: v | AH21: v | AI21: v | AJ21: v | AK21: v | AL21: v | AM21: v | AN21: v | AO21: v | AP21: v | AQ21: v | AR21: v | AS21: v | AT21: v | AU21: v | AV21: v | BB21: =IF(AND(I21="",I22=""),"",COUNTIF(I21:I22,"v")) -> 2 | BC21: =IF(AND(J21="",J22=""),"",COUNTIF(J21:J22,"v")) -> 2 | BD21: =IF(AND(K21="",K22=""),"",COUNTIF(K21:K22,"v")) -> 2 | BE21: =IF(AND(L21="",L22=""),"",COUNTIF(L21:L22,"v")) -> 2 | BF21: =IF(AND(M21="",M22=""),"",COUNTIF(M21:M22,"v")) -> 2 | BG21: =IF(AND(N21="",N22=""),"",COUNTIF(N21:N22,"v")) -> 2 | BH21: =IF(AND(O21="",O22=""),"",COUNTIF(O21:O22,"v")) -> 2 | BI21: =IF(AND(P21="",P22=""),"",COUNTIF(P21:P22,"v")) -> 2 | ... CT21: =IF(AND(BA21="",BA22=""),"",COUNTIF(BA21:BA22,"v")) | CU21: =IF(BB21="","",IF(BB21=0,"Ditolak",IF(BB21=1,"Diperbaiki","Digunakan"))) -> Digunakan | CV21: =IF(BC21="","",IF(BC21=0,"Ditolak",IF(AND(BC21>=1,BC21<2),"Diperbaiki","Digunakan"))) -> Digunakan | CW21: =IF(BD21="","",IF(BD21=0,"Ditolak",IF(AND(BD21>=1,BD21<2),"Diperbaiki","Digunakan"))) -> Digunakan | CX21: =IF(BE21="","",IF(BE21=0,"Ditolak",IF(AND(BE21>=1,BE21<2),"Diperbaiki","Digunakan"))) -> Digunakan | CY21: =IF(BF21="","",IF(BF21=0,"Ditolak",IF(AND(BF21>=1,BF21<2),"Diperbaiki","Digunakan"))) -> Digunakan | CZ21: =IF(BG21="","",IF(BG21=0,"Ditolak",IF(AND(BG21>=1,BG21<2),"Diperbaiki","Digunakan"))) -> Digunakan | DA21: =IF(BH21="","",IF(BH21=0,"Ditolak",IF(AND(BH21>=1,BH21<2),"Diperbaiki","Digunakan"))) -> Digunakan | DB21: =IF(BI21="","",IF(BI21=0,"Ditolak",IF(AND(BI21>=1,BI21<2),"Diperbaiki","Digunakan"))) -> Digunakan | DC21: =IF(BJ21="","",IF(BJ21=0,"Ditolak",IF(AND(BJ21>=1,BJ21<2),"Diperbaiki","Digunakan"))) -> Digunakan | ... EM21: =IF(CT21="","",IF(CT21=0,"Ditolak",IF(AND(CT21>=1,CT21<2),"Diperbaiki","Digunakan"))) | EN21: =IF(COUNTIF(CU21:EH38,"Diperbaiki")>=1,"konstruksi","") | EO21: =IF(COUNTIF(CV21:EN38,"Diperbaiki")>=1,"konstruksi","") | EP21: =IF(COUNTIF(CW21:EO38,"Diperbaiki")>=1,"konstruksi","") | EQ21: =IF(COUNTIF(CX21:EP38,"Diperbaiki")>=1,"konstruksi","") | ER21: =IF(COUNTIF(CY21:EQ38,"Diperbaiki")>=1,"konstruksi","") | ES21: =IF(COUNTIF(CZ21:ER38,"Diperbaiki")>=1,"konstruksi","") | ET21: =IF(COUNTIF(DA21:ES38,"Diperbaiki")>=1,"konstruksi","") | EU21: =IF(COUNTIF(DB21:ET38,"Diperbaiki")>=1,"konstruksi","") | EV21: =IF(COUNTIF(DC21:EU38,"Diperbaiki")>=1,"konstruksi","") | ... GF21: =IF(COUNTIF(EM21:GE38,"Diperbaiki")>=1,"konstruksi","") | GG21: =IF(EN21="","",",") | GH21: =IF(EO21="","",",") | GI21: =IF(EP21="","",",") | GJ21: =IF(EQ21="","",",") | GK21: =IF(ER21="","",",") | GL21: =IF(ES21="","",",") | GM21: =IF(ET21="","",",") | GN21: =IF(EU21="","",",") | ... HY21: =IF(GF21="","",",")
G22: ● | H22: pokok soal dirumuskan tegas | I22: v | J22: v | K22: v | L22: v | M22: v | N22: v | O22: v | P22: v | Q22: v | R22: v | S22: v | T22: v | U22: v | V22: v | W22: v | X22: v | Y22: v | Z22: v | AA22: v | AB22: v | AC22: v | AD22: v | AE22: v | AF22: v | AG22: v | AH22: v | AI22: v | AJ22: v | AK22: v | AL22: v | AM22: v | AN22: v | AO22: v | AP22: v | AQ22: v | AR22: v | AS22: v | AT22: v | AU22: v | AV22: v
E23: 2 | F23: Pokok soal dan pilihan jawaban merupakan pernyataan yang diperlukan | G23: ● | H23: pokok soal merupakan pernyataan yang diperlukan | I23: v | J23: v | K23: v | L23: v | M23: v | N23: v | O23: v | P23: v | Q23: v | R23: v | S23: v | T23: v | U23: v | V23: v | W23: v | X23: v | Y23: v | Z23: v | AA23: v | AB23: v | AC23: v | AD23: v | AE23: v | AF23: v | AG23: v | AH23: v | AI23: v | AJ23: v | AK23: v | AL23: v | AM23: v | AN23: v | AO23: v | AP23: v | AQ23: v | AR23: v | AS23: v | AT23: v | AU23: v | AV23: v | BB23: =IF(AND(I23="",I24=""),"",COUNTIF(I23:I24,"v")) -> 2 | BC23: =IF(AND(J23="",J24=""),"",COUNTIF(J23:J24,"v")) -> 2 | BD23: =IF(AND(K23="",K24=""),"",COUNTIF(K23:K24,"v")) -> 2 | BE23: =IF(AND(L23="",L24=""),"",COUNTIF(L23:L24,"v")) -> 2 | BF23: =IF(AND(M23="",M24=""),"",COUNTIF(M23:M24,"v")) -> 2 | BG23: =IF(AND(N23="",N24=""),"",COUNTIF(N23:N24,"v")) -> 2 | BH23: =IF(AND(O23="",O24=""),"",COUNTIF(O23:O24,"v")) -> 2 | BI23: =IF(AND(P23="",P24=""),"",COUNTIF(P23:P24,"v")) -> 2 | ... CT23: =IF(AND(BA23="",BA24=""),"",COUNTIF(BA23:BA24,"v")) | CU23: =IF(BB23="","",IF(BB23=0,"Ditolak",IF(BB23=1,"Diperbaiki","Digunakan"))) -> Digunakan | CV23: =IF(BC23="","",IF(BC23=0,"Ditolak",IF(AND(BC23>=1,BC23<2),"Diperbaiki","Digunakan"))) -> Digunakan | CW23: =IF(BD23="","",IF(BD23=0,"Ditolak",IF(AND(BD23>=1,BD23<2),"Diperbaiki","Digunakan"))) -> Digunakan | CX23: =IF(BE23="","",IF(BE23=0,"Ditolak",IF(AND(BE23>=1,BE23<2),"Diperbaiki","Digunakan"))) -> Digunakan | CY23: =IF(BF23="","",IF(BF23=0,"Ditolak",IF(AND(BF23>=1,BF23<2),"Diperbaiki","Digunakan"))) -> Digunakan | CZ23: =IF(BG23="","",IF(BG23=0,"Ditolak",IF(AND(BG23>=1,BG23<2),"Diperbaiki","Digunakan"))) -> Digunakan | DA23: =IF(BH23="","",IF(BH23=0,"Ditolak",IF(AND(BH23>=1,BH23<2),"Diperbaiki","Digunakan"))) -> Digunakan | DB23: =IF(BI23="","",IF(BI23=0,"Ditolak",IF(AND(BI23>=1,BI23<2),"Diperbaiki","Digunakan"))) -> Digunakan | DC23: =IF(BJ23="","",IF(BJ23=0,"Ditolak",IF(AND(BJ23>=1,BJ23<2),"Diperbaiki","Digunakan"))) -> Digunakan | ... EM23: =IF(CT23="","",IF(CT23=0,"Ditolak",IF(AND(CT23>=1,CT23<2),"Diperbaiki","Digunakan")))
G24: ● | H24: pilihan jawaban merupakan pernyataan yang diperlukan | I24: v | J24: v | K24: v | L24: v | M24: v | N24: v | O24: v | P24: v | Q24: v | R24: v | S24: v | T24: v | U24: v | V24: v | W24: v | X24: v | Y24: v | Z24: v | AA24: v | AB24: v | AC24: v | AD24: v | AE24: v | AF24: v | AG24: v | AH24: v | AI24: v | AJ24: v | AK24: v | AL24: v | AM24: v | AN24: v | AO24: v | AP24: v | AQ24: v | AR24: v | AS24: v | AT24: v | AU24: v | AV24: v
E25: 3 | F25: Pokok soal tidak memberi petunjuk ke arah jawaban benar. | G25: ● | H25: pokok soal tidak memuat kata atau kalimat yang menunjuk ke arah jawaban benar | I25: v | J25: v | K25: v | L25: v | M25: v | N25: v | O25: v | P25: v | Q25: v | R25: v | S25: v | T25: v | U25: v | V25: v | W25: v | X25: v | Y25: v | Z25: v | AA25: v | AB25: v | AC25: v | AD25: v | AE25: v | AF25: v | AG25: v | AH25: v | AI25: v | AJ25: v | AK25: v | AL25: v | AM25: v | AN25: v | AO25: v | AP25: v | AQ25: v | AR25: v | AS25: v | AT25: v | AU25: v | AV25: v | BB25: =IF(AND(I25="",I26=""),"",COUNTIF(I25:I26,"v")) -> 2 | BC25: =IF(AND(J25="",J26=""),"",COUNTIF(J25:J26,"v")) -> 2 | BD25: =IF(AND(K25="",K26=""),"",COUNTIF(K25:K26,"v")) -> 2 | BE25: =IF(AND(L25="",L26=""),"",COUNTIF(L25:L26,"v")) -> 2 | BF25: =IF(AND(M25="",M26=""),"",COUNTIF(M25:M26,"v")) -> 2 | BG25: =IF(AND(N25="",N26=""),"",COUNTIF(N25:N26,"v")) -> 2 | BH25: =IF(AND(O25="",O26=""),"",COUNTIF(O25:O26,"v")) -> 2 | BI25: =IF(AND(P25="",P26=""),"",COUNTIF(P25:P26,"v")) -> 2 | ... CT25: =IF(AND(BA25="",BA26=""),"",COUNTIF(BA25:BA26,"v")) | CU25: =IF(BB25="","",IF(BB25=0,"Ditolak",IF(BB25=1,"Diperbaiki","Digunakan"))) -> Digunakan | CV25: =IF(BC25="","",IF(BC25=0,"Ditolak",IF(AND(BC25>=1,BC25<2),"Diperbaiki","Digunakan"))) -> Digunakan | CW25: =IF(BD25="","",IF(BD25=0,"Ditolak",IF(AND(BD25>=1,BD25<2),"Diperbaiki","Digunakan"))) -> Digunakan | CX25: =IF(BE25="","",IF(BE25=0,"Ditolak",IF(AND(BE25>=1,BE25<2),"Diperbaiki","Digunakan"))) -> Digunakan | CY25: =IF(BF25="","",IF(BF25=0,"Ditolak",IF(AND(BF25>=1,BF25<2),"Diperbaiki","Digunakan"))) -> Digunakan | CZ25: =IF(BG25="","",IF(BG25=0,"Ditolak",IF(AND(BG25>=1,BG25<2),"Diperbaiki","Digunakan"))) -> Digunakan | DA25: =IF(BH25="","",IF(BH25=0,"Ditolak",IF(AND(BH25>=1,BH25<2),"Diperbaiki","Digunakan"))) -> Digunakan | DB25: =IF(BI25="","",IF(BI25=0,"Ditolak",IF(AND(BI25>=1,BI25<2),"Diperbaiki","Digunakan"))) -> Digunakan | DC25: =IF(BJ25="","",IF(BJ25=0,"Ditolak",IF(AND(BJ25>=1,BJ25<2),"Diperbaiki","Digunakan"))) -> Digunakan | ... EM25: =IF(CT25="","",IF(CT25=0,"Ditolak",IF(AND(CT25>=1,CT25<2),"Diperbaiki","Digunakan")))
G26: ● | H26: Pokok soal memiliki jawaban benar | I26: v | J26: v | K26: v | L26: v | M26: v | N26: v | O26: v | P26: v | Q26: v | R26: v | S26: v | T26: v | U26: v | V26: v | W26: v | X26: v | Y26: v | Z26: v | AA26: v | AB26: v | AC26: v | AD26: v | AE26: v | AF26: v | AG26: v | AH26: v | AI26: v | AJ26: v | AK26: v | AL26: v | AM26: v | AN26: v | AO26: v | AP26: v | AQ26: v | AR26: v | AS26: v | AT26: v | AU26: v | AV26: v
E27: 4 | F27: Pokok soal tidak mengandung pernyataan yang bersifat negatif ganda. | G27: ● | H27: pokok soal yang memuat kata "tidak" atau "bukan" diberi tanda khusus | I27: v | J27: v | K27: v | L27: v | M27: v | N27: v | O27: v | P27: v | Q27: v | R27: v | S27: v | T27: v | U27: v | V27: v | W27: v | X27: v | Y27: v | Z27: v | AA27: v | AB27: v | AC27: v | AD27: v | AE27: v | AF27: v | AG27: v | AH27: v | AI27: v | AJ27: v | AK27: v | AL27: v | AM27: v | AN27: v | AO27: v | AP27: v | AQ27: v | AR27: v | AS27: v | AT27: v | AU27: v | AV27: v | BB27: =IF(AND(I27="",I28=""),"",COUNTIF(I27:I28,"v")) -> 2 | BC27: =IF(AND(J27="",J28=""),"",COUNTIF(J27:J28,"v")) -> 2 | BD27: =IF(AND(K27="",K28=""),"",COUNTIF(K27:K28,"v")) -> 2 | BE27: =IF(AND(L27="",L28=""),"",COUNTIF(L27:L28,"v")) -> 2 | BF27: =IF(AND(M27="",M28=""),"",COUNTIF(M27:M28,"v")) -> 2 | BG27: =IF(AND(N27="",N28=""),"",COUNTIF(N27:N28,"v")) -> 2 | BH27: =IF(AND(O27="",O28=""),"",COUNTIF(O27:O28,"v")) -> 2 | BI27: =IF(AND(P27="",P28=""),"",COUNTIF(P27:P28,"v")) -> 2 | ... CT27: =IF(AND(BA27="",BA28=""),"",COUNTIF(BA27:BA28,"v")) | CU27: =IF(BB27="","",IF(BB27=0,"Ditolak",IF(BB27=1,"Diperbaiki","Digunakan"))) -> Digunakan | CV27: =IF(BC27="","",IF(BC27=0,"Ditolak",IF(AND(BC27>=1,BC27<2),"Diperbaiki","Digunakan"))) -> Digunakan | CW27: =IF(BD27="","",IF(BD27=0,"Ditolak",IF(AND(BD27>=1,BD27<2),"Diperbaiki","Digunakan"))) -> Digunakan | CX27: =IF(BE27="","",IF(BE27=0,"Ditolak",IF(AND(BE27>=1,BE27<2),"Diperbaiki","Digunakan"))) -> Digunakan | CY27: =IF(BF27="","",IF(BF27=0,"Ditolak",IF(AND(BF27>=1,BF27<2),"Diperbaiki","Digunakan"))) -> Digunakan | CZ27: =IF(BG27="","",IF(BG27=0,"Ditolak",IF(AND(BG27>=1,BG27<2),"Diperbaiki","Digunakan"))) -> Digunakan | DA27: =IF(BH27="","",IF(BH27=0,"Ditolak",IF(AND(BH27>=1,BH27<2),"Diperbaiki","Digunakan"))) -> Digunakan | DB27: =IF(BI27="","",IF(BI27=0,"Ditolak",IF(AND(BI27>=1,BI27<2),"Diperbaiki","Digunakan"))) -> Digunakan | DC27: =IF(BJ27="","",IF(BJ27=0,"Ditolak",IF(AND(BJ27>=1,BJ27<2),"Diperbaiki","Digunakan"))) -> Digunakan | ... EM27: =IF(CT27="","",IF(CT27=0,"Ditolak",IF(AND(CT27>=1,CT27<2),"Diperbaiki","Digunakan")))
G28: ● | H28: pokok soal tidak memuat kata "tidak" dan "kecuali" | I28: v | J28: v | K28: v | L28: v | M28: v | N28: v | O28: v | P28: v | Q28: v | R28: v | S28: v | T28: v | U28: v | V28: v | W28: v | X28: v | Y28: v | Z28: v | AA28: v | AB28: v | AC28: v | AD28: v | AE28: v | AF28: v | AG28: v | AH28: v | AI28: v | AJ28: v | AK28: v | AL28: v | AM28: v | AN28: v | AO28: v | AP28: v | AQ28: v | AR28: v | AS28: v | AT28: v | AU28: v | AV28: v
E29: 5 | F29: Panjang rumusan pilihan jawaban harus relatif sama. | G29: ● | H29: pilihan jawaban merupakan kata yang diperlukan saja | I29: v | J29: v | K29: v | L29: v | M29: v | N29: v | O29: v | P29: v | Q29: v | R29: v | S29: v | T29: v | U29: v | V29: v | W29: v | X29: v | Y29: v | Z29: v | AA29: v | AB29: v | AC29: v | AD29: v | AE29: v | AF29: v | AG29: v | AH29: v | AI29: v | AJ29: v | AK29: v | AL29: v | AM29: v | AN29: v | AO29: v | AP29: v | AQ29: v | AR29: v | AS29: v | AT29: v | AU29: v | AV29: v | BB29: =IF(AND(I29="",I30=""),"",COUNTIF(I29:I30,"v")) -> 2 | BC29: =IF(AND(J29="",J30=""),"",COUNTIF(J29:J30,"v")) -> 2 | BD29: =IF(AND(K29="",K30=""),"",COUNTIF(K29:K30,"v")) -> 2 | BE29: =IF(AND(L29="",L30=""),"",COUNTIF(L29:L30,"v")) -> 2 | BF29: =IF(AND(M29="",M30=""),"",COUNTIF(M29:M30,"v")) -> 2 | BG29: =IF(AND(N29="",N30=""),"",COUNTIF(N29:N30,"v")) -> 2 | BH29: =IF(AND(O29="",O30=""),"",COUNTIF(O29:O30,"v")) -> 2 | BI29: =IF(AND(P29="",P30=""),"",COUNTIF(P29:P30,"v")) -> 2 | ... CT29: =IF(AND(BA29="",BA30=""),"",COUNTIF(BA29:BA30,"v")) | CU29: =IF(BB29="","",IF(BB29=0,"Ditolak",IF(BB29=1,"Diperbaiki","Digunakan"))) -> Digunakan | CV29: =IF(BC29="","",IF(BC29=0,"Ditolak",IF(AND(BC29>=1,BC29<2),"Diperbaiki","Digunakan"))) -> Digunakan | CW29: =IF(BD29="","",IF(BD29=0,"Ditolak",IF(AND(BD29>=1,BD29<2),"Diperbaiki","Digunakan"))) -> Digunakan | CX29: =IF(BE29="","",IF(BE29=0,"Ditolak",IF(AND(BE29>=1,BE29<2),"Diperbaiki","Digunakan"))) -> Digunakan | CY29: =IF(BF29="","",IF(BF29=0,"Ditolak",IF(AND(BF29>=1,BF29<2),"Diperbaiki","Digunakan"))) -> Digunakan | CZ29: =IF(BG29="","",IF(BG29=0,"Ditolak",IF(AND(BG29>=1,BG29<2),"Diperbaiki","Digunakan"))) -> Digunakan | DA29: =IF(BH29="","",IF(BH29=0,"Ditolak",IF(AND(BH29>=1,BH29<2),"Diperbaiki","Digunakan"))) -> Digunakan | DB29: =IF(BI29="","",IF(BI29=0,"Ditolak",IF(AND(BI29>=1,BI29<2),"Diperbaiki","Digunakan"))) -> Digunakan | DC29: =IF(BJ29="","",IF(BJ29=0,"Ditolak",IF(AND(BJ29>=1,BJ29<2),"Diperbaiki","Digunakan"))) -> Digunakan | ... EM29: =IF(CT29="","",IF(CT29=0,"Ditolak",IF(AND(CT29>=1,CT29<2),"Diperbaiki","Digunakan")))
G30: ● | H30: rumusan pilihan tidak terkesan memberi informasi yang lengkap | I30: v | J30: v | K30: v | L30: v | M30: v | N30: v | O30: v | P30: v | Q30: v | R30: v | S30: v | T30: v | U30: v | V30: v | W30: v | X30: v | Y30: v | Z30: v | AA30: v | AB30: v | AC30: v | AD30: v | AE30: v | AF30: v | AG30: v | AH30: v | AI30: v | AJ30: v | AK30: v | AL30: v | AM30: v | AN30: v | AO30: v | AP30: v | AQ30: v | AR30: v | AS30: v | AT30: v | AU30: v | AV30: v
E31: 6 | F31: Pilihan jawaban jangan mengandung pernyataan, “Semua pilihan jawaban di atas salah” atau “Semua pilihan jawabandi atas benar”. | G31: ● | H31: Pilihan jawaban tidak memuat pernyataan “Semua pilihan jawaban di atas salah” atau “Semua pilihan jawaban di atas benar”. | I31: v | J31: v | K31: v | L31: v | M31: v | N31: v | O31: v | P31: v | Q31: v | R31: v | S31: v | T31: v | U31: v | V31: v | W31: v | X31: v | Y31: v | Z31: v | AA31: v | AB31: v | AC31: v | AD31: v | AE31: v | AF31: v | AG31: v | AH31: v | AI31: v | AJ31: v | AK31: v | AL31: v | AM31: v | AN31: v | AO31: v | AP31: v | AQ31: v | AR31: v | AS31: v | AT31: v | AU31: v | AV31: v | BB31: =IF(AND(I31="",I32=""),"",COUNTIF(I31:I32,"v")) -> 2 | BC31: =IF(AND(J31="",J32=""),"",COUNTIF(J31:J32,"v")) -> 2 | BD31: =IF(AND(K31="",K32=""),"",COUNTIF(K31:K32,"v")) -> 2 | BE31: =IF(AND(L31="",L32=""),"",COUNTIF(L31:L32,"v")) -> 2 | BF31: =IF(AND(M31="",M32=""),"",COUNTIF(M31:M32,"v")) -> 2 | BG31: =IF(AND(N31="",N32=""),"",COUNTIF(N31:N32,"v")) -> 2 | BH31: =IF(AND(O31="",O32=""),"",COUNTIF(O31:O32,"v")) -> 2 | BI31: =IF(AND(P31="",P32=""),"",COUNTIF(P31:P32,"v")) -> 2 | ... CT31: =IF(AND(BA31="",BA32=""),"",COUNTIF(BA31:BA32,"v")) | CU31: =IF(BB31="","",IF(BB31=0,"Ditolak",IF(BB31=1,"Diperbaiki","Digunakan"))) -> Digunakan | CV31: =IF(BC31="","",IF(BC31=0,"Ditolak",IF(AND(BC31>=1,BC31<2),"Diperbaiki","Digunakan"))) -> Digunakan | CW31: =IF(BD31="","",IF(BD31=0,"Ditolak",IF(AND(BD31>=1,BD31<2),"Diperbaiki","Digunakan"))) -> Digunakan | CX31: =IF(BE31="","",IF(BE31=0,"Ditolak",IF(AND(BE31>=1,BE31<2),"Diperbaiki","Digunakan"))) -> Digunakan | CY31: =IF(BF31="","",IF(BF31=0,"Ditolak",IF(AND(BF31>=1,BF31<2),"Diperbaiki","Digunakan"))) -> Digunakan | CZ31: =IF(BG31="","",IF(BG31=0,"Ditolak",IF(AND(BG31>=1,BG31<2),"Diperbaiki","Digunakan"))) -> Digunakan | DA31: =IF(BH31="","",IF(BH31=0,"Ditolak",IF(AND(BH31>=1,BH31<2),"Diperbaiki","Digunakan"))) -> Digunakan | DB31: =IF(BI31="","",IF(BI31=0,"Ditolak",IF(AND(BI31>=1,BI31<2),"Diperbaiki","Digunakan"))) -> Digunakan | DC31: =IF(BJ31="","",IF(BJ31=0,"Ditolak",IF(AND(BJ31>=1,BJ31<2),"Diperbaiki","Digunakan"))) -> Digunakan | ... EM31: =IF(CT31="","",IF(CT31=0,"Ditolak",IF(AND(CT31>=1,CT31<2),"Diperbaiki","Digunakan")))
G32: ● | H32: Pilihan jawaban dirumuskan agar peserta didik mengetahui akan jawaban dan tidak terkesan kurang atau lebih | I32: v | J32: v | K32: v | L32: v | M32: v | N32: v | O32: v | P32: v | Q32: v | R32: v | S32: v | T32: v | U32: v | V32: v | W32: v | X32: v | Y32: v | Z32: v | AA32: v | AB32: v | AC32: v | AD32: v | AE32: v | AF32: v | AG32: v | AH32: v | AI32: v | AJ32: v | AK32: v | AL32: v | AM32: v | AN32: v | AO32: v | AP32: v | AQ32: v | AR32: v | AS32: v | AT32: v | AU32: v | AV32: v
E33: 7 | F33: Pilihan jawaban yang berbentuk angka atau waktu harus disusun berdasarkan urutan besar kecilnya nilai angka tersebut atau kronologisnya. | G33: ● | H33: Pilihan jawaban diurutkan dari besar ke kecil atau kecil ke besar | I33: v | J33: v | K33: v | L33: v | M33: v | N33: v | O33: v | P33: v | Q33: v | R33: v | S33: v | T33: v | U33: v | V33: v | W33: v | X33: v | Y33: v | Z33: v | AA33: v | AB33: v | AC33: v | AD33: v | AE33: v | AF33: v | AG33: v | AH33: v | AI33: v | AJ33: v | AK33: v | AL33: v | AM33: v | AN33: v | AO33: v | AP33: v | AQ33: v | AR33: v | AS33: v | AT33: v | AU33: v | AV33: v | BB33: =IF(AND(I33="",I34=""),"",COUNTIF(I33:I34,"v")) -> 2 | BC33: =IF(AND(J33="",J34=""),"",COUNTIF(J33:J34,"v")) -> 2 | BD33: =IF(AND(K33="",K34=""),"",COUNTIF(K33:K34,"v")) -> 2 | BE33: =IF(AND(L33="",L34=""),"",COUNTIF(L33:L34,"v")) -> 2 | BF33: =IF(AND(M33="",M34=""),"",COUNTIF(M33:M34,"v")) -> 2 | BG33: =IF(AND(N33="",N34=""),"",COUNTIF(N33:N34,"v")) -> 2 | BH33: =IF(AND(O33="",O34=""),"",COUNTIF(O33:O34,"v")) -> 2 | BI33: =IF(AND(P33="",P34=""),"",COUNTIF(P33:P34,"v")) -> 2 | ... CT33: =IF(AND(BA33="",BA34=""),"",COUNTIF(BA33:BA34,"v")) | CU33: =IF(BB33="","",IF(BB33=0,"Ditolak",IF(BB33=1,"Diperbaiki","Digunakan"))) -> Digunakan | CV33: =IF(BC33="","",IF(BC33=0,"Ditolak",IF(AND(BC33>=1,BC33<2),"Diperbaiki","Digunakan"))) -> Digunakan | CW33: =IF(BD33="","",IF(BD33=0,"Ditolak",IF(AND(BD33>=1,BD33<2),"Diperbaiki","Digunakan"))) -> Digunakan | CX33: =IF(BE33="","",IF(BE33=0,"Ditolak",IF(AND(BE33>=1,BE33<2),"Diperbaiki","Digunakan"))) -> Digunakan | CY33: =IF(BF33="","",IF(BF33=0,"Ditolak",IF(AND(BF33>=1,BF33<2),"Diperbaiki","Digunakan"))) -> Digunakan | CZ33: =IF(BG33="","",IF(BG33=0,"Ditolak",IF(AND(BG33>=1,BG33<2),"Diperbaiki","Digunakan"))) -> Digunakan | DA33: =IF(BH33="","",IF(BH33=0,"Ditolak",IF(AND(BH33>=1,BH33<2),"Diperbaiki","Digunakan"))) -> Digunakan | DB33: =IF(BI33="","",IF(BI33=0,"Ditolak",IF(AND(BI33>=1,BI33<2),"Diperbaiki","Digunakan"))) -> Digunakan | DC33: =IF(BJ33="","",IF(BJ33=0,"Ditolak",IF(AND(BJ33>=1,BJ33<2),"Diperbaiki","Digunakan"))) -> Digunakan | ... EM33: =IF(CT33="","",IF(CT33=0,"Ditolak",IF(AND(CT33>=1,CT33<2),"Diperbaiki","Digunakan")))
G34: ● | H34: Pilihan jawaban mempermudah peserta didik memilih pilihan jawaban | I34: v | J34: v | K34: v | L34: v | M34: v | N34: v | O34: v | P34: v | Q34: v | R34: v | S34: v | T34: v | U34: v | V34: v | W34: v | X34: v | Y34: v | Z34: v | AA34: v | AB34: v | AC34: v | AD34: v | AE34: v | AF34: v | AG34: v | AH34: v | AI34: v | AJ34: v | AK34: v | AL34: v | AM34: v | AN34: v | AO34: v | AP34: v | AQ34: v | AR34: v | AS34: v | AT34: v | AU34: v | AV34: v
E35: 8 | F35: Gambar, grafik, tabel, diagram, dan sejenisnya yang terdapat pada soal harus jelas dan berfungsi. | G35: ● | H35: Ukuran pada gambar tidak boleh ada yang kurang sehingga peserta didik tidak bisa menjawab | I35: v | J35: v | K35: v | L35: v | M35: v | N35: v | O35: v | P35: v | Q35: v | R35: v | S35: v | T35: v | U35: v | V35: v | W35: v | X35: v | Y35: v | Z35: v | AA35: v | AB35: v | AC35: v | AD35: v | AE35: v | AF35: v | AG35: v | AH35: v | AI35: v | AJ35: v | AK35: v | AL35: v | AM35: v | AN35: v | AO35: v | AP35: v | AQ35: v | AR35: v | AS35: v | AT35: v | AU35: v | AV35: v | BB35: =IF(AND(I35="",I36=""),"",COUNTIF(I35:I36,"v")) -> 2 | BC35: =IF(AND(J35="",J36=""),"",COUNTIF(J35:J36,"v")) -> 2 | BD35: =IF(AND(K35="",K36=""),"",COUNTIF(K35:K36,"v")) -> 2 | BE35: =IF(AND(L35="",L36=""),"",COUNTIF(L35:L36,"v")) -> 2 | BF35: =IF(AND(M35="",M36=""),"",COUNTIF(M35:M36,"v")) -> 2 | BG35: =IF(AND(N35="",N36=""),"",COUNTIF(N35:N36,"v")) -> 2 | BH35: =IF(AND(O35="",O36=""),"",COUNTIF(O35:O36,"v")) -> 2 | BI35: =IF(AND(P35="",P36=""),"",COUNTIF(P35:P36,"v")) -> 2 | ... CT35: =IF(AND(BA35="",BA36=""),"",COUNTIF(BA35:BA36,"v")) | CU35: =IF(BB35="","",IF(BB35=0,"Ditolak",IF(BB35=1,"Diperbaiki","Digunakan"))) -> Digunakan | CV35: =IF(BC35="","",IF(BC35=0,"Ditolak",IF(AND(BC35>=1,BC35<2),"Diperbaiki","Digunakan"))) -> Digunakan | CW35: =IF(BD35="","",IF(BD35=0,"Ditolak",IF(AND(BD35>=1,BD35<2),"Diperbaiki","Digunakan"))) -> Digunakan | CX35: =IF(BE35="","",IF(BE35=0,"Ditolak",IF(AND(BE35>=1,BE35<2),"Diperbaiki","Digunakan"))) -> Digunakan | CY35: =IF(BF35="","",IF(BF35=0,"Ditolak",IF(AND(BF35>=1,BF35<2),"Diperbaiki","Digunakan"))) -> Digunakan | CZ35: =IF(BG35="","",IF(BG35=0,"Ditolak",IF(AND(BG35>=1,BG35<2),"Diperbaiki","Digunakan"))) -> Digunakan | DA35: =IF(BH35="","",IF(BH35=0,"Ditolak",IF(AND(BH35>=1,BH35<2),"Diperbaiki","Digunakan"))) -> Digunakan | DB35: =IF(BI35="","",IF(BI35=0,"Ditolak",IF(AND(BI35>=1,BI35<2),"Diperbaiki","Digunakan"))) -> Digunakan | DC35: =IF(BJ35="","",IF(BJ35=0,"Ditolak",IF(AND(BJ35>=1,BJ35<2),"Diperbaiki","Digunakan"))) -> Digunakan | ... EM35: =IF(CT35="","",IF(CT35=0,"Ditolak",IF(AND(CT35>=1,CT35<2),"Diperbaiki","Digunakan")))
G36: ● | H36: Antara gambar dan pilihan jawaban terhubung dengan kalimat yang sesuai | I36: v | J36: v | K36: v | L36: v | M36: v | N36: v | O36: v | P36: v | Q36: v | R36: v | S36: v | T36: v | U36: v | V36: v | W36: v | X36: v | Y36: v | Z36: v | AA36: v | AB36: v | AC36: v | AD36: v | AE36: v | AF36: v | AG36: v | AH36: v | AI36: v | AJ36: v | AK36: v | AL36: v | AM36: v | AN36: v | AO36: v | AP36: v | AQ36: v | AR36: v | AS36: v | AT36: v | AU36: v | AV36: v
E37: 9 | F37: Butir soal tidak bergantung pada jawaban soal sebelumnya. | G37: ● | H37: Soal tidak bergantung pada pilihan jawaban soal sebelumnya | I37: v | J37: v | K37: v | L37: v | M37: v | N37: v | O37: v | P37: v | Q37: v | R37: v | S37: v | T37: v | U37: v | V37: v | W37: v | X37: v | Y37: v | Z37: v | AA37: v | AB37: v | AC37: v | AD37: v | AE37: v | AF37: v | AG37: v | AH37: v | AI37: v | AJ37: v | AK37: v | AL37: v | AM37: v | AN37: v | AO37: v | AP37: v | AQ37: v | AR37: v | AS37: v | AT37: v | AU37: v | AV37: v | BB37: =IF(AND(I37="",I38=""),"",COUNTIF(I37:I38,"v")) -> 2 | BC37: =IF(AND(J37="",J38=""),"",COUNTIF(J37:J38,"v")) -> 2 | BD37: =IF(AND(K37="",K38=""),"",COUNTIF(K37:K38,"v")) -> 2 | BE37: =IF(AND(L37="",L38=""),"",COUNTIF(L37:L38,"v")) -> 2 | BF37: =IF(AND(M37="",M38=""),"",COUNTIF(M37:M38,"v")) -> 2 | BG37: =IF(AND(N37="",N38=""),"",COUNTIF(N37:N38,"v")) -> 2 | BH37: =IF(AND(O37="",O38=""),"",COUNTIF(O37:O38,"v")) -> 2 | BI37: =IF(AND(P37="",P38=""),"",COUNTIF(P37:P38,"v")) -> 2 | ... CT37: =IF(AND(BA37="",BA38=""),"",COUNTIF(BA37:BA38,"v")) | CU37: =IF(BB37="","",IF(BB37=0,"Ditolak",IF(BB37=1,"Diperbaiki","Digunakan"))) -> Digunakan | CV37: =IF(BC37="","",IF(BC37=0,"Ditolak",IF(AND(BC37>=1,BC37<2),"Diperbaiki","Digunakan"))) -> Digunakan | CW37: =IF(BD37="","",IF(BD37=0,"Ditolak",IF(AND(BD37>=1,BD37<2),"Diperbaiki","Digunakan"))) -> Digunakan | CX37: =IF(BE37="","",IF(BE37=0,"Ditolak",IF(AND(BE37>=1,BE37<2),"Diperbaiki","Digunakan"))) -> Digunakan | CY37: =IF(BF37="","",IF(BF37=0,"Ditolak",IF(AND(BF37>=1,BF37<2),"Diperbaiki","Digunakan"))) -> Digunakan | CZ37: =IF(BG37="","",IF(BG37=0,"Ditolak",IF(AND(BG37>=1,BG37<2),"Diperbaiki","Digunakan"))) -> Digunakan | DA37: =IF(BH37="","",IF(BH37=0,"Ditolak",IF(AND(BH37>=1,BH37<2),"Diperbaiki","Digunakan"))) -> Digunakan | DB37: =IF(BI37="","",IF(BI37=0,"Ditolak",IF(AND(BI37>=1,BI37<2),"Diperbaiki","Digunakan"))) -> Digunakan | DC37: =IF(BJ37="","",IF(BJ37=0,"Ditolak",IF(AND(BJ37>=1,BJ37<2),"Diperbaiki","Digunakan"))) -> Digunakan | ... EM37: =IF(CT37="","",IF(CT37=0,"Ditolak",IF(AND(CT37>=1,CT37<2),"Diperbaiki","Digunakan")))
G38: ● | H38: Jawaban yang benar tidak terkait dengan pokok soal lainnya | I38: v | J38: v | K38: v | L38: v | M38: v | N38: v | O38: v | P38: v | Q38: v | R38: v | S38: v | T38: v | U38: v | V38: v | W38: v | X38: v | Y38: v | Z38: v | AA38: v | AB38: v | AC38: v | AD38: v | AE38: v | AF38: v | AG38: v | AH38: v | AI38: v | AJ38: v | AK38: v | AL38: v | AM38: v | AN38: v | AO38: v | AP38: v | AQ38: v | AR38: v | AS38: v | AT38: v | AU38: v | AV38: v
C39: C. | D39: BAHASA | E39: 1 | F39: Setiap soal harus menggunakan bahasa yang sesuai dengan kaidah bahasa Indonesia. | G39: ● | H39: menggunakan ejaan, kata dan kalimat yang baku | I39: v | J39: v | K39: v | L39: v | M39: v | N39: v | O39: v | P39: v | Q39: v | R39: v | S39: v | T39: v | U39: v | V39: v | W39: v | X39: v | Y39: v | Z39: v | AA39: v | AB39: v | AC39: v | AD39: v | AE39: v | AF39: v | AG39: v | AH39: v | AI39: v | AJ39: v | AK39: v | AL39: v | AM39: v | AN39: v | AO39: v | AP39: v | AQ39: v | AR39: v | AS39: v | AT39: v | AU39: v | AV39: v | BB39: =IF(AND(I39="",I40=""),"",COUNTIF(I39:I40,"v")) -> 2 | BC39: =IF(AND(J39="",J40=""),"",COUNTIF(J39:J40,"v")) -> 2 | BD39: =IF(AND(K39="",K40=""),"",COUNTIF(K39:K40,"v")) -> 2 | BE39: =IF(AND(L39="",L40=""),"",COUNTIF(L39:L40,"v")) -> 2 | BF39: =IF(AND(M39="",M40=""),"",COUNTIF(M39:M40,"v")) -> 2 | BG39: =IF(AND(N39="",N40=""),"",COUNTIF(N39:N40,"v")) -> 2 | BH39: =IF(AND(O39="",O40=""),"",COUNTIF(O39:O40,"v")) -> 2 | BI39: =IF(AND(P39="",P40=""),"",COUNTIF(P39:P40,"v")) -> 2 | ... CT39: =IF(AND(BA39="",BA40=""),"",COUNTIF(BA39:BA40,"v")) | CU39: =IF(BB39="","",IF(BB39=0,"Ditolak",IF(BB39=1,"Diperbaiki","Digunakan"))) -> Digunakan | CV39: =IF(BC39="","",IF(BC39=0,"Ditolak",IF(AND(BC39>=1,BC39<2),"Diperbaiki","Digunakan"))) -> Digunakan | CW39: =IF(BD39="","",IF(BD39=0,"Ditolak",IF(AND(BD39>=1,BD39<2),"Diperbaiki","Digunakan"))) -> Digunakan | CX39: =IF(BE39="","",IF(BE39=0,"Ditolak",IF(AND(BE39>=1,BE39<2),"Diperbaiki","Digunakan"))) -> Digunakan | CY39: =IF(BF39="","",IF(BF39=0,"Ditolak",IF(AND(BF39>=1,BF39<2),"Diperbaiki","Digunakan"))) -> Digunakan | CZ39: =IF(BG39="","",IF(BG39=0,"Ditolak",IF(AND(BG39>=1,BG39<2),"Diperbaiki","Digunakan"))) -> Digunakan | DA39: =IF(BH39="","",IF(BH39=0,"Ditolak",IF(AND(BH39>=1,BH39<2),"Diperbaiki","Digunakan"))) -> Digunakan | DB39: =IF(BI39="","",IF(BI39=0,"Ditolak",IF(AND(BI39>=1,BI39<2),"Diperbaiki","Digunakan"))) -> Digunakan | DC39: =IF(BJ39="","",IF(BJ39=0,"Ditolak",IF(AND(BJ39>=1,BJ39<2),"Diperbaiki","Digunakan"))) -> Digunakan | ... EM39: =IF(CT39="","",IF(CT39=0,"Ditolak",IF(AND(CT39>=1,CT39<2),"Diperbaiki","Digunakan"))) | EN39: =IF(COUNTIF(CU39:CU46,"Diperbaiki")>=1,"bahasa","") | EO39: =IF(COUNTIF(CV39:CV46,"Diperbaiki")>=1,"bahasa","") | EP39: =IF(COUNTIF(CW39:CW46,"Diperbaiki")>=1,"bahasa","") | EQ39: =IF(COUNTIF(CX39:CX46,"Diperbaiki")>=1,"bahasa","") | ER39: =IF(COUNTIF(CY39:CY46,"Diperbaiki")>=1,"bahasa","") | ES39: =IF(COUNTIF(CZ39:CZ46,"Diperbaiki")>=1,"bahasa","") | ET39: =IF(COUNTIF(DA39:DA46,"Diperbaiki")>=1,"bahasa","") | EU39: =IF(COUNTIF(DB39:DB46,"Diperbaiki")>=1,"bahasa","") | ... GF39: =IF(COUNTIF(EM39:EM46,"Diperbaiki")>=1,"bahasa","") | GG39: =IF(EN39="","",",") | GH39: =IF(EO39="","",",") | GI39: =IF(EP39="","",",") | GJ39: =IF(EQ39="","",",") | GK39: =IF(ER39="","",",") | GL39: =IF(ES39="","",",") | GM39: =IF(ET39="","",",") | GN39: =IF(EU39="","",",") | ... HY39: =IF(GF39="","",",")
G40: ● | H40: menggunakan aturan penulisan kalimat yang benar | I40: v | J40: v | K40: v | L40: v | M40: v | N40: v | O40: v | P40: v | Q40: v | R40: v | S40: v | T40: v | U40: v | V40: v | W40: v | X40: v | Y40: v | Z40: v | AA40: v | AB40: v | AC40: v | AD40: v | AE40: v | AF40: v | AG40: v | AH40: v | AI40: v | AJ40: v | AK40: v | AL40: v | AM40: v | AN40: v | AO40: v | AP40: v | AQ40: v | AR40: v | AS40: v | AT40: v | AU40: v | AV40: v
E41: 2 | F41: Jangan menggunakan bahasa yang berlaku setempat jika soal akan digunakan untuk daerah lain atau nasional. | G41: ● | H41: Tidak memuat kata atau kalimat dengan bahasa daerah tertentu | I41: v | J41: v | K41: v | L41: v | M41: v | N41: v | O41: v | P41: v | Q41: v | R41: v | S41: v | T41: v | U41: v | V41: v | W41: v | X41: v | Y41: v | Z41: v | AA41: v | AB41: v | AC41: v | AD41: v | AE41: v | AF41: v | AG41: v | AH41: v | AI41: v | AJ41: v | AK41: v | AL41: v | AM41: v | AN41: v | AO41: v | AP41: v | AQ41: v | AR41: v | AS41: v | AT41: v | AU41: v | AV41: v | BB41: =IF(AND(I41="",I42=""),"",COUNTIF(I41:I42,"v")) -> 2 | BC41: =IF(AND(J41="",J42=""),"",COUNTIF(J41:J42,"v")) -> 2 | BD41: =IF(AND(K41="",K42=""),"",COUNTIF(K41:K42,"v")) -> 2 | BE41: =IF(AND(L41="",L42=""),"",COUNTIF(L41:L42,"v")) -> 2 | BF41: =IF(AND(M41="",M42=""),"",COUNTIF(M41:M42,"v")) -> 2 | BG41: =IF(AND(N41="",N42=""),"",COUNTIF(N41:N42,"v")) -> 2 | BH41: =IF(AND(O41="",O42=""),"",COUNTIF(O41:O42,"v")) -> 2 | BI41: =IF(AND(P41="",P42=""),"",COUNTIF(P41:P42,"v")) -> 2 | ... CT41: =IF(AND(BA41="",BA42=""),"",COUNTIF(BA41:BA42,"v")) | CU41: =IF(BB41="","",IF(BB41=0,"Ditolak",IF(BB41=1,"Diperbaiki","Digunakan"))) -> Digunakan | CV41: =IF(BC41="","",IF(BC41=0,"Ditolak",IF(AND(BC41>=1,BC41<2),"Diperbaiki","Digunakan"))) -> Digunakan | CW41: =IF(BD41="","",IF(BD41=0,"Ditolak",IF(AND(BD41>=1,BD41<2),"Diperbaiki","Digunakan"))) -> Digunakan | CX41: =IF(BE41="","",IF(BE41=0,"Ditolak",IF(AND(BE41>=1,BE41<2),"Diperbaiki","Digunakan"))) -> Digunakan | CY41: =IF(BF41="","",IF(BF41=0,"Ditolak",IF(AND(BF41>=1,BF41<2),"Diperbaiki","Digunakan"))) -> Digunakan | CZ41: =IF(BG41="","",IF(BG41=0,"Ditolak",IF(AND(BG41>=1,BG41<2),"Diperbaiki","Digunakan"))) -> Digunakan | DA41: =IF(BH41="","",IF(BH41=0,"Ditolak",IF(AND(BH41>=1,BH41<2),"Diperbaiki","Digunakan"))) -> Digunakan | DB41: =IF(BI41="","",IF(BI41=0,"Ditolak",IF(AND(BI41>=1,BI41<2),"Diperbaiki","Digunakan"))) -> Digunakan | DC41: =IF(BJ41="","",IF(BJ41=0,"Ditolak",IF(AND(BJ41>=1,BJ41<2),"Diperbaiki","Digunakan"))) -> Digunakan | ... EM41: =IF(CT41="","",IF(CT41=0,"Ditolak",IF(AND(CT41>=1,CT41<2),"Diperbaiki","Digunakan")))
...

Sheet Telaah_UR
A1: Petunjuk
A2: Isilah kolom telaah soal dengan tanda "V" untuk yang sesuai atau tanda "X" untuk yang tidak sesuai pada setiap cel yang diblok warna hijau
A4: NO | B4: ASPEK | C4: INDIKATOR | G4: DESKRIPTOR | I4: telaah soal | AC4: skor soal | AW4: kategori | BQ4: aspek lemah | DE4: gabungan aspek lemah | DY4: rekomendasi No.
I5: 41 | J5: 42 | K5: 43 | L5: 44 | M5: 45 | N5: 6 | O5: 7 | P5: 8 | Q5: 9 | R5: 10 | S5: 11 | T5: 12 | U5: 13 | V5: 14 | W5: 15 | X5: 16 | Y5: 17 | Z5: 18 | AA5: 19 | AB5: 20 | AC5: 1 | AD5: 2 | AE5: 3 | AF5: 4 | AG5: 5 | AH5: 6 | AI5: 7 | AJ5: 8 | AK5: 9 | AL5: 10 | AM5: 11 | AN5: 12 | AO5: 13 | AP5: 14 | AQ5: 15 | AR5: 16 | AS5: 17 | AT5: 18 | AU5: 19 | AV5: 20 | AW5: 1 | AX5: 2 | AY5: 3 | AZ5: 4 | BA5: 5 | BB5: 6 | BC5: 7 | BD5: 8 | BE5: 9 | BF5: 10 | BG5: 11 | BH5: 12 | BI5: 13 | BJ5: 14 | BK5: 15 | BL5: 16 | BM5: 17 | BN5: 18 | BO5: 19 | BP5: 20 | BQ5: 1 | BR5: 2 | BS5: 3 | BT5: 4 | BU5: 5 | BV5: 6 | BW5: 7 | BX5: 8 | BY5: 9 | BZ5: 10 | CA5: 11 | CB5: 12 | CC5: 13 | CD5: 14 | CE5: 15 | CF5: 16 | CG5: 17 | CH5: 18 | CI5: 19 | CJ5: 20 | CK5: 1 | CL5: 2 | CM5: 3 | CN5: 4 | CO5: 5 | CP5: 6 | CQ5: 7 | CR5: 8 | CS5: 9 | CT5: 10 | CU5: 11 | CV5: 12 | CW5: 13 | CX5: 14 | CY5: 15 | CZ5: 16 | DA5: 17 | DB5: 18 | DC5: 19 | DD5: 20 | DE5: 1 | DF5: 2 | DG5: 3 | DH5: 4 | DI5: 5 | DJ5: 6 | DK5: 7 | DL5: 8 | DM5: 9 | DN5: 10 | DO5: 11 | DP5: 12 | DQ5: 13 | DR5: 14 | DS5: 15 | DT5: 16 | DU5: 17 | DV5: 18 | DW5: 19 | DX5: 20 | DY5: 1 | DZ5: 2 | EA5: 3 | EB5: 4 | EC5: 5 | ED5: 6 | EE5: 7 | EF5: 8 | EG5: 9 | EH5: 10 | EI5: 11 | EJ5: 12 | EK5: 13 | EL5: 14 | EM5: 15 | EN5: 16 | EO5: 17 | EP5: 18 | EQ5: 19 | ER5: 20
